<?xml version="1.0" ?>
<robot xmlns:xacro="http://ros.org/wiki/xacro">
	<xacro:macro name="sef_roboter_sr25" params="prefix">
	      <!-- link list -->
	      <link name="${prefix}base_link">
		      <visual>
			<origin xyz="0 0 0" rpy="0 0 0" />      
			      <geometry>
				    <mesh filename="package://sef_roboter_support/meshes/sr25/visual/sr25_base_axis.stl" />
			      </geometry>
			      <material name="black">
			         <color rgba="0.1 0.1 0.1 1" />
	                      </material>
		      </visual>
		      <collision>
			      <origin xyz="0 0 0" rpy="0 0 0" />      
			      <geometry>
				    <mesh filename="package://sef_roboter_support/meshes/sr25/collision/sr25_base_axis.stl"  />
			      </geometry>
			      <material name="yellow">
			         <color rgba="0 1 1 1" />
	                      </material>
		      </collision>
	      </link>
	      
	      <link name="${prefix}link_1">
		      <visual>
			      <geometry>
				    <mesh filename="package://sef_roboter_support/meshes/sr25/visual/sr25_axis_1.stl"  />
			      </geometry>
			      <material name="sef_yellow">
			         <color rgba="0.8 0.8 0 1" />
	                      </material>
		      </visual>
		      <collision>
			      <origin xyz="0 0 0" rpy="0 0 0" />
			      <geometry>
				    <mesh filename="package://sef_roboter_support/meshes/sr25/collision/sr25_axis_1.stl"  />
			      </geometry>
			      <material name="yellow" />
			         
		      </collision>
	      </link>
	      
	      <link name="${prefix}link_2">
		      <visual>
			      <geometry>
				    <mesh filename="package://sef_roboter_support/meshes/sr25/visual/sr25_axis_2.stl"  />
			      </geometry>
			      <material name="sef_yellow" />			         
		      </visual>
		      <collision>
			      <geometry>
				    <mesh filename="package://sef_roboter_support/meshes/sr25/collision/sr25_axis_2.stl"  />
			      </geometry>
			      <material name="yellow" />
			         
		      </collision>
	      </link>
	      
	      <link name="${prefix}link_3">
		      <visual>
			      <geometry>
				    <mesh filename="package://sef_roboter_support/meshes/sr25/visual/sr25_axis_3.stl" />
			      </geometry>
			      <material name="black" />			         
		      </visual>
		      <collision>
			      <geometry>
				    <mesh filename="package://sef_roboter_support/meshes/sr25/collision/sr25_axis_3.stl" />
			      </geometry>
			      <material name="yellow" />
			         
		      </collision>
	      </link>
	      
	      <link name="${prefix}link_4">
		      <visual>
			      <geometry>
				    <mesh filename="package://sef_roboter_support/meshes/sr25/visual/sr25_axis_4.stl" />
			      </geometry>
			      <material name="sef_yellow" />			         
		      </visual>
		      <collision>
			      <geometry>
				    <mesh filename="package://sef_roboter_support/meshes/sr25/collision/sr25_axis_4.stl" />
			      </geometry>
			      <material name="yellow" />
			         
		      </collision>
	      </link>
	      
	      <link name="${prefix}link_5">
		      <visual>
			      <geometry>
				    <mesh filename="package://sef_roboter_support/meshes/sr25/visual/sr25_axis_5.stl" />
			      </geometry>
			      <material name="sef_yellow" />			         
		      </visual>
		      <collision>
			      <geometry>
				    <mesh filename="package://sef_roboter_support/meshes/sr25/collision/sr25_axis_5.stl" />
			      </geometry>
			      <material name="yellow" />
			         
		      </collision>
	      </link>
	      
	      <link name="${prefix}link_tool">
		      <visual>
			      <geometry>
				    <mesh filename="package://sef_roboter_support/meshes/sr25/visual/sr25_axis_tool.stl" />
			      </geometry>
			      <material name="black" />			         
		      </visual>
		      <collision>
			      <geometry>
				    <mesh filename="package://sef_roboter_support/meshes/sr25/collision/sr25_axis_tool.stl" />
			      </geometry>
			      <material name="yellow" />
			         
		      </collision>
	      </link>
	      <!-- end of link list -->
	      <!-- joint list -->
	      <joint name="${prefix}joint_1" type="continuous">
			<parent link="${prefix}base_link"/>
			<child link="${prefix}link_1"/>
			<origin xyz="0 0 0.075738" rpy="1.5708 0 -1.5745"/>
			<axis xyz="0 -1 0" />
			<limit lower="-2.8" upper="2.8" effort="100" velocity="1" />
	      </joint>
	      
	      <joint name="${prefix}joint_2" type="continuous">
			<parent link="${prefix}link_1"/>
			<child link="${prefix}link_2"/>
			<origin xyz="0 0.24264 -0.29599" rpy="1.5687 0 0"/>
			<axis xyz="-1 0 0" />
			<limit lower="-0.5" upper="1.5" effort="100" velocity="1" />
	      </joint>
	      
	      <joint name="${prefix}joint_3" type="continuous">
			<parent link="${prefix}link_2"/>
			<child link="${prefix}link_3"/>
			<origin xyz="0 0 -0.79724" rpy="0.005529 0 0"/>
			<axis xyz="-1 0 0" />
			<limit lower="-0.5" upper="1.5" effort="100" velocity="1" />
              </joint>
	      
	      <joint name="${prefix}joint_4" type="continuous">
			<parent link="${prefix}link_3"/>
			<child link="${prefix}link_4"/>
			<origin xyz="0 -0.15811 0" rpy="0 0.0014787 0"/>
			<axis xyz="0 1 0" />
			<limit lower="-1.6" upper="1.6" effort="100" velocity="1" />
              </joint>
	      
	      <joint name="${prefix}joint_5" type="continuous">
			<parent link="${prefix}link_4"/>
			<child link="${prefix}link_5"/>
			<origin xyz="0 -0.58433 0" rpy="0 0 -0.033693"/>
			<axis xyz="0 0 1" />
			<limit lower="-3" upper="3" effort="100" velocity="1" />
              </joint>
		
	      <joint name="${prefix}joint_6" type="continuous">
			<parent link="${prefix}link_5"/>
			<child link="${prefix}link_tool"/>
			<origin xyz="0 -0.164051291252016 -0.00548103448275694" rpy="-1.5707963267949 0 3.14159265358979"/>
			<axis xyz="0 0 -1 " />
			<limit lower="-2.5" upper="2.5" effort="100" velocity="1" />
              </joint>
	      <!-- end of joint list -->
	</xacro:macro>
</robot>
	      
	      